{
 "cells": [
  {
   "cell_type": "code",
   "execution_count": 1,
   "metadata": {
    "tags": []
   },
   "outputs": [
    {
     "ename": "ModuleNotFoundError",
     "evalue": "No module named 'cv2'",
     "output_type": "error",
     "traceback": [
      "\u001b[1;31m---------------------------------------------------------------------------\u001b[0m",
      "\u001b[1;31mModuleNotFoundError\u001b[0m                       Traceback (most recent call last)",
      "Cell \u001b[1;32mIn[1], line 4\u001b[0m\n\u001b[0;32m      2\u001b[0m \u001b[38;5;28;01mimport\u001b[39;00m \u001b[38;5;21;01mmatplotlib\u001b[39;00m\u001b[38;5;21;01m.\u001b[39;00m\u001b[38;5;21;01mpyplot\u001b[39;00m \u001b[38;5;28;01mas\u001b[39;00m \u001b[38;5;21;01mplt\u001b[39;00m\n\u001b[0;32m      3\u001b[0m \u001b[38;5;28;01mimport\u001b[39;00m \u001b[38;5;21;01mos\u001b[39;00m\n\u001b[1;32m----> 4\u001b[0m \u001b[38;5;28;01mimport\u001b[39;00m \u001b[38;5;21;01mcv2\u001b[39;00m\n",
      "\u001b[1;31mModuleNotFoundError\u001b[0m: No module named 'cv2'"
     ]
    }
   ],
   "source": [
    "import  numpy as np\n",
    "import matplotlib.pyplot as plt\n",
    "import os\n",
    "import cv2\n",
    "\n",
    "\n"
   ]
  },
  {
   "cell_type": "code",
   "execution_count": 4,
   "metadata": {
    "tags": []
   },
   "outputs": [
    {
     "name": "stdout",
     "output_type": "stream",
     "text": [
      "Unexpected exception formatting exception. Falling back to standard exception\n"
     ]
    },
    {
     "name": "stderr",
     "output_type": "stream",
     "text": [
      "Traceback (most recent call last):\n",
      "  File \"C:\\Users\\Pc\\AppData\\Roaming\\Python\\Python311\\site-packages\\IPython\\core\\interactiveshell.py\", line 3526, in run_code\n",
      "    exec(code_obj, self.user_global_ns, self.user_ns)\n",
      "  File \"C:\\Users\\Pc\\AppData\\Local\\Temp\\ipykernel_11388\\519030662.py\", line 6, in <module>\n",
      "    for img in os.listdir(path):\n",
      "               ^^^^^^^^^^^^^^^^\n",
      "FileNotFoundError: [WinError 3] The system cannot find the path specified: 'C:/Users/Pc/juypter/cat.jpg\\\\cat'\n",
      "\n",
      "During handling of the above exception, another exception occurred:\n",
      "\n",
      "Traceback (most recent call last):\n",
      "  File \"C:\\Users\\Pc\\AppData\\Roaming\\Python\\Python311\\site-packages\\IPython\\core\\interactiveshell.py\", line 2120, in showtraceback\n",
      "    stb = self.InteractiveTB.structured_traceback(\n",
      "          ^^^^^^^^^^^^^^^^^^^^^^^^^^^^^^^^^^^^^^^^\n",
      "  File \"C:\\Users\\Pc\\AppData\\Roaming\\Python\\Python311\\site-packages\\IPython\\core\\ultratb.py\", line 1435, in structured_traceback\n",
      "    return FormattedTB.structured_traceback(\n",
      "           ^^^^^^^^^^^^^^^^^^^^^^^^^^^^^^^^^\n",
      "  File \"C:\\Users\\Pc\\AppData\\Roaming\\Python\\Python311\\site-packages\\IPython\\core\\ultratb.py\", line 1326, in structured_traceback\n",
      "    return VerboseTB.structured_traceback(\n",
      "           ^^^^^^^^^^^^^^^^^^^^^^^^^^^^^^^\n",
      "  File \"C:\\Users\\Pc\\AppData\\Roaming\\Python\\Python311\\site-packages\\IPython\\core\\ultratb.py\", line 1173, in structured_traceback\n",
      "    formatted_exception = self.format_exception_as_a_whole(etype, evalue, etb, number_of_lines_of_context,\n",
      "                          ^^^^^^^^^^^^^^^^^^^^^^^^^^^^^^^^^^^^^^^^^^^^^^^^^^^^^^^^^^^^^^^^^^^^^^^^^^^^^^^^\n",
      "  File \"C:\\Users\\Pc\\AppData\\Roaming\\Python\\Python311\\site-packages\\IPython\\core\\ultratb.py\", line 1088, in format_exception_as_a_whole\n",
      "    frames.append(self.format_record(record))\n",
      "                  ^^^^^^^^^^^^^^^^^^^^^^^^^^\n",
      "  File \"C:\\Users\\Pc\\AppData\\Roaming\\Python\\Python311\\site-packages\\IPython\\core\\ultratb.py\", line 970, in format_record\n",
      "    frame_info.lines, Colors, self.has_colors, lvals\n",
      "    ^^^^^^^^^^^^^^^^\n",
      "  File \"C:\\Users\\Pc\\AppData\\Roaming\\Python\\Python311\\site-packages\\IPython\\core\\ultratb.py\", line 792, in lines\n",
      "    return self._sd.lines\n",
      "           ^^^^^^^^^^^^^^\n",
      "  File \"C:\\Users\\Pc\\AppData\\Roaming\\Python\\Python311\\site-packages\\stack_data\\utils.py\", line 144, in cached_property_wrapper\n",
      "    value = obj.__dict__[self.func.__name__] = self.func(obj)\n",
      "                                               ^^^^^^^^^^^^^^\n",
      "  File \"C:\\Users\\Pc\\AppData\\Roaming\\Python\\Python311\\site-packages\\stack_data\\core.py\", line 734, in lines\n",
      "    pieces = self.included_pieces\n",
      "             ^^^^^^^^^^^^^^^^^^^^\n",
      "  File \"C:\\Users\\Pc\\AppData\\Roaming\\Python\\Python311\\site-packages\\stack_data\\utils.py\", line 144, in cached_property_wrapper\n",
      "    value = obj.__dict__[self.func.__name__] = self.func(obj)\n",
      "                                               ^^^^^^^^^^^^^^\n",
      "  File \"C:\\Users\\Pc\\AppData\\Roaming\\Python\\Python311\\site-packages\\stack_data\\core.py\", line 677, in included_pieces\n",
      "    scope_pieces = self.scope_pieces\n",
      "                   ^^^^^^^^^^^^^^^^^\n",
      "  File \"C:\\Users\\Pc\\AppData\\Roaming\\Python\\Python311\\site-packages\\stack_data\\utils.py\", line 144, in cached_property_wrapper\n",
      "    value = obj.__dict__[self.func.__name__] = self.func(obj)\n",
      "                                               ^^^^^^^^^^^^^^\n",
      "  File \"C:\\Users\\Pc\\AppData\\Roaming\\Python\\Python311\\site-packages\\stack_data\\core.py\", line 614, in scope_pieces\n",
      "    scope_start, scope_end = self.source.line_range(self.scope)\n",
      "                             ^^^^^^^^^^^^^^^^^^^^^^^^^^^^^^^^^^\n",
      "  File \"C:\\Users\\Pc\\AppData\\Roaming\\Python\\Python311\\site-packages\\stack_data\\core.py\", line 178, in line_range\n",
      "    return line_range(self.asttext(), node)\n",
      "                      ^^^^^^^^^^^^\n",
      "AttributeError: 'Source' object has no attribute 'asttext'\n"
     ]
    }
   ],
   "source": [
    "DATADIR = \"C:/Users/Pc/juypter/cat.jpg\"\n",
    "CATEGORIES = [\"cat\",\"dogs\"]\n",
    "\n",
    "for category in CATEGORIES:\n",
    "    path = os.path.join(DATADIR,category)\n",
    "    for img in os.listdir(path):\n",
    "        img_array = cv2.imread(os.path.join(path,img),cv2.IMREAD_GRAYSCALE)\n",
    "        plt.imshow(img_array,cmap=\"gray\")\n",
    "        plt.show()\n",
    "        break\n",
    "    break"
   ]
  },
  {
   "cell_type": "code",
   "execution_count": null,
   "metadata": {},
   "outputs": [],
   "source": []
  },
  {
   "cell_type": "code",
   "execution_count": 16,
   "metadata": {},
   "outputs": [
    {
     "name": "stdout",
     "output_type": "stream",
     "text": [
      "Unexpected exception formatting exception. Falling back to standard exception\n"
     ]
    },
    {
     "name": "stderr",
     "output_type": "stream",
     "text": [
      "Traceback (most recent call last):\n",
      "  File \"C:\\Users\\Pc\\AppData\\Roaming\\Python\\Python311\\site-packages\\IPython\\core\\interactiveshell.py\", line 3526, in run_code\n",
      "    exec(code_obj, self.user_global_ns, self.user_ns)\n",
      "  File \"C:\\Users\\Pc\\AppData\\Local\\Temp\\ipykernel_8812\\3104836576.py\", line 11, in <module>\n",
      "    for img in os.listdir(path):\n",
      "               ^^^^^^^^^^^^^^^^\n",
      "FileNotFoundError: [WinError 3] The system cannot find the path specified: 'C:/Users/Pc/juypter/Cat\\\\Cat'\n",
      "\n",
      "During handling of the above exception, another exception occurred:\n",
      "\n",
      "Traceback (most recent call last):\n",
      "  File \"C:\\Users\\Pc\\AppData\\Roaming\\Python\\Python311\\site-packages\\IPython\\core\\interactiveshell.py\", line 2120, in showtraceback\n",
      "    stb = self.InteractiveTB.structured_traceback(\n",
      "          ^^^^^^^^^^^^^^^^^^^^^^^^^^^^^^^^^^^^^^^^\n",
      "  File \"C:\\Users\\Pc\\AppData\\Roaming\\Python\\Python311\\site-packages\\IPython\\core\\ultratb.py\", line 1435, in structured_traceback\n",
      "    return FormattedTB.structured_traceback(\n",
      "           ^^^^^^^^^^^^^^^^^^^^^^^^^^^^^^^^^\n",
      "  File \"C:\\Users\\Pc\\AppData\\Roaming\\Python\\Python311\\site-packages\\IPython\\core\\ultratb.py\", line 1326, in structured_traceback\n",
      "    return VerboseTB.structured_traceback(\n",
      "           ^^^^^^^^^^^^^^^^^^^^^^^^^^^^^^^\n",
      "  File \"C:\\Users\\Pc\\AppData\\Roaming\\Python\\Python311\\site-packages\\IPython\\core\\ultratb.py\", line 1173, in structured_traceback\n",
      "    formatted_exception = self.format_exception_as_a_whole(etype, evalue, etb, number_of_lines_of_context,\n",
      "                          ^^^^^^^^^^^^^^^^^^^^^^^^^^^^^^^^^^^^^^^^^^^^^^^^^^^^^^^^^^^^^^^^^^^^^^^^^^^^^^^^\n",
      "  File \"C:\\Users\\Pc\\AppData\\Roaming\\Python\\Python311\\site-packages\\IPython\\core\\ultratb.py\", line 1088, in format_exception_as_a_whole\n",
      "    frames.append(self.format_record(record))\n",
      "                  ^^^^^^^^^^^^^^^^^^^^^^^^^^\n",
      "  File \"C:\\Users\\Pc\\AppData\\Roaming\\Python\\Python311\\site-packages\\IPython\\core\\ultratb.py\", line 970, in format_record\n",
      "    frame_info.lines, Colors, self.has_colors, lvals\n",
      "    ^^^^^^^^^^^^^^^^\n",
      "  File \"C:\\Users\\Pc\\AppData\\Roaming\\Python\\Python311\\site-packages\\IPython\\core\\ultratb.py\", line 792, in lines\n",
      "    return self._sd.lines\n",
      "           ^^^^^^^^^^^^^^\n",
      "  File \"C:\\Users\\Pc\\AppData\\Roaming\\Python\\Python311\\site-packages\\stack_data\\utils.py\", line 144, in cached_property_wrapper\n",
      "    value = obj.__dict__[self.func.__name__] = self.func(obj)\n",
      "                                               ^^^^^^^^^^^^^^\n",
      "  File \"C:\\Users\\Pc\\AppData\\Roaming\\Python\\Python311\\site-packages\\stack_data\\core.py\", line 734, in lines\n",
      "    pieces = self.included_pieces\n",
      "             ^^^^^^^^^^^^^^^^^^^^\n",
      "  File \"C:\\Users\\Pc\\AppData\\Roaming\\Python\\Python311\\site-packages\\stack_data\\utils.py\", line 144, in cached_property_wrapper\n",
      "    value = obj.__dict__[self.func.__name__] = self.func(obj)\n",
      "                                               ^^^^^^^^^^^^^^\n",
      "  File \"C:\\Users\\Pc\\AppData\\Roaming\\Python\\Python311\\site-packages\\stack_data\\core.py\", line 677, in included_pieces\n",
      "    scope_pieces = self.scope_pieces\n",
      "                   ^^^^^^^^^^^^^^^^^\n",
      "  File \"C:\\Users\\Pc\\AppData\\Roaming\\Python\\Python311\\site-packages\\stack_data\\utils.py\", line 144, in cached_property_wrapper\n",
      "    value = obj.__dict__[self.func.__name__] = self.func(obj)\n",
      "                                               ^^^^^^^^^^^^^^\n",
      "  File \"C:\\Users\\Pc\\AppData\\Roaming\\Python\\Python311\\site-packages\\stack_data\\core.py\", line 614, in scope_pieces\n",
      "    scope_start, scope_end = self.source.line_range(self.scope)\n",
      "                             ^^^^^^^^^^^^^^^^^^^^^^^^^^^^^^^^^^\n",
      "  File \"C:\\Users\\Pc\\AppData\\Roaming\\Python\\Python311\\site-packages\\stack_data\\core.py\", line 178, in line_range\n",
      "    return line_range(self.asttext(), node)\n",
      "                      ^^^^^^^^^^^^\n",
      "AttributeError: 'Source' object has no attribute 'asttext'\n"
     ]
    }
   ],
   "source": [
    "import numpy as np\n",
    "import matplotlib.pyplot as plt\n",
    "import os\n",
    "import cv2\n",
    "\n",
    "DATADIR = \"C:/Users/Pc/juypter/Cat\"\n",
    "CATEGORIES = ['Cat']\n",
    "\n",
    "for category in CATEGORIES:\n",
    "    path = os.path.join(DATADIR, category)\n",
    "    for img in os.listdir(path):\n",
    "        img_array = cv2.imread(os.path.join(path, img), cv2.IMREAD_GRAYSCALE)\n",
    "        plt.imshow(img_array, cmap=\"gray\")\n",
    "        plt.show()\n"
   ]
  },
  {
   "cell_type": "code",
   "execution_count": 15,
   "metadata": {},
   "outputs": [
    {
     "name": "stdout",
     "output_type": "stream",
     "text": [
      "Unexpected exception formatting exception. Falling back to standard exception\n"
     ]
    },
    {
     "name": "stderr",
     "output_type": "stream",
     "text": [
      "Traceback (most recent call last):\n",
      "  File \"C:\\Users\\Pc\\AppData\\Roaming\\Python\\Python311\\site-packages\\IPython\\core\\interactiveshell.py\", line 3526, in run_code\n",
      "    exec(code_obj, self.user_global_ns, self.user_ns)\n",
      "  File \"C:\\Users\\Pc\\AppData\\Local\\Temp\\ipykernel_668\\2404726527.py\", line 11, in <module>\n",
      "    for img in os.listdir(path):\n",
      "               ^^^^^^^^^^^^^^^^\n",
      "FileNotFoundError: [WinError 3] The system cannot find the path specified: 'C:/Users/Pc/juypter/cat.jpg\\\\cat'\n",
      "\n",
      "During handling of the above exception, another exception occurred:\n",
      "\n",
      "Traceback (most recent call last):\n",
      "  File \"C:\\Users\\Pc\\AppData\\Roaming\\Python\\Python311\\site-packages\\IPython\\core\\interactiveshell.py\", line 2120, in showtraceback\n",
      "    stb = self.InteractiveTB.structured_traceback(\n",
      "          ^^^^^^^^^^^^^^^^^^^^^^^^^^^^^^^^^^^^^^^^\n",
      "  File \"C:\\Users\\Pc\\AppData\\Roaming\\Python\\Python311\\site-packages\\IPython\\core\\ultratb.py\", line 1435, in structured_traceback\n",
      "    return FormattedTB.structured_traceback(\n",
      "           ^^^^^^^^^^^^^^^^^^^^^^^^^^^^^^^^^\n",
      "  File \"C:\\Users\\Pc\\AppData\\Roaming\\Python\\Python311\\site-packages\\IPython\\core\\ultratb.py\", line 1326, in structured_traceback\n",
      "    return VerboseTB.structured_traceback(\n",
      "           ^^^^^^^^^^^^^^^^^^^^^^^^^^^^^^^\n",
      "  File \"C:\\Users\\Pc\\AppData\\Roaming\\Python\\Python311\\site-packages\\IPython\\core\\ultratb.py\", line 1173, in structured_traceback\n",
      "    formatted_exception = self.format_exception_as_a_whole(etype, evalue, etb, number_of_lines_of_context,\n",
      "                          ^^^^^^^^^^^^^^^^^^^^^^^^^^^^^^^^^^^^^^^^^^^^^^^^^^^^^^^^^^^^^^^^^^^^^^^^^^^^^^^^\n",
      "  File \"C:\\Users\\Pc\\AppData\\Roaming\\Python\\Python311\\site-packages\\IPython\\core\\ultratb.py\", line 1088, in format_exception_as_a_whole\n",
      "    frames.append(self.format_record(record))\n",
      "                  ^^^^^^^^^^^^^^^^^^^^^^^^^^\n",
      "  File \"C:\\Users\\Pc\\AppData\\Roaming\\Python\\Python311\\site-packages\\IPython\\core\\ultratb.py\", line 970, in format_record\n",
      "    frame_info.lines, Colors, self.has_colors, lvals\n",
      "    ^^^^^^^^^^^^^^^^\n",
      "  File \"C:\\Users\\Pc\\AppData\\Roaming\\Python\\Python311\\site-packages\\IPython\\core\\ultratb.py\", line 792, in lines\n",
      "    return self._sd.lines\n",
      "           ^^^^^^^^^^^^^^\n",
      "  File \"C:\\Users\\Pc\\AppData\\Roaming\\Python\\Python311\\site-packages\\stack_data\\utils.py\", line 144, in cached_property_wrapper\n",
      "    value = obj.__dict__[self.func.__name__] = self.func(obj)\n",
      "                                               ^^^^^^^^^^^^^^\n",
      "  File \"C:\\Users\\Pc\\AppData\\Roaming\\Python\\Python311\\site-packages\\stack_data\\core.py\", line 734, in lines\n",
      "    pieces = self.included_pieces\n",
      "             ^^^^^^^^^^^^^^^^^^^^\n",
      "  File \"C:\\Users\\Pc\\AppData\\Roaming\\Python\\Python311\\site-packages\\stack_data\\utils.py\", line 144, in cached_property_wrapper\n",
      "    value = obj.__dict__[self.func.__name__] = self.func(obj)\n",
      "                                               ^^^^^^^^^^^^^^\n",
      "  File \"C:\\Users\\Pc\\AppData\\Roaming\\Python\\Python311\\site-packages\\stack_data\\core.py\", line 677, in included_pieces\n",
      "    scope_pieces = self.scope_pieces\n",
      "                   ^^^^^^^^^^^^^^^^^\n",
      "  File \"C:\\Users\\Pc\\AppData\\Roaming\\Python\\Python311\\site-packages\\stack_data\\utils.py\", line 144, in cached_property_wrapper\n",
      "    value = obj.__dict__[self.func.__name__] = self.func(obj)\n",
      "                                               ^^^^^^^^^^^^^^\n",
      "  File \"C:\\Users\\Pc\\AppData\\Roaming\\Python\\Python311\\site-packages\\stack_data\\core.py\", line 614, in scope_pieces\n",
      "    scope_start, scope_end = self.source.line_range(self.scope)\n",
      "                             ^^^^^^^^^^^^^^^^^^^^^^^^^^^^^^^^^^\n",
      "  File \"C:\\Users\\Pc\\AppData\\Roaming\\Python\\Python311\\site-packages\\stack_data\\core.py\", line 178, in line_range\n",
      "    return line_range(self.asttext(), node)\n",
      "                      ^^^^^^^^^^^^\n",
      "AttributeError: 'Source' object has no attribute 'asttext'\n"
     ]
    }
   ],
   "source": [
    "import numpy as np\n",
    "import matplotlib.pyplot as plt\n",
    "import os\n",
    "import cv2\n",
    "\n",
    "DATADIR = r\"C:/Users/Pc/juypter/cat.jpg\"\n",
    "CATEGORIES = [\"cat\", \"dogs\"]\n",
    "\n",
    "for category in CATEGORIES:\n",
    "    path = os.path.join(DATADIR, category)\n",
    "    for img in os.listdir(path):\n",
    "        img_array = cv2.imread(os.path.join(path, img), cv2.IMREAD_GRAYSCALE)\n",
    "        plt.imshow(img_array, cmap=\"gray\")\n",
    "        plt.show()\n"
   ]
  }
 ],
 "metadata": {
  "kernelspec": {
   "display_name": "Python 3 (ipykernel)",
   "language": "python",
   "name": "python3"
  },
  "language_info": {
   "codemirror_mode": {
    "name": "ipython",
    "version": 3
   },
   "file_extension": ".py",
   "mimetype": "text/x-python",
   "name": "python",
   "nbconvert_exporter": "python",
   "pygments_lexer": "ipython3",
   "version": "3.11.5"
  }
 },
 "nbformat": 4,
 "nbformat_minor": 4
}
